[migrate-local] РџСЂРёРјРµРЅСЏРµРј РјРёРіСЂР°С†РёРё CRM (Alembic)...
Traceback (most recent call last):
  File "C:\Program Files\Python312\Lib\asyncio\windows_events.py", line 461, in finish_socket_func
    return ov.getresult()
           ^^^^^^^^^^^^^^
OSError: [WinError 64] Указанное сетевое имя более недоступно

During handling of the above exception, another exception occurred:

Traceback (most recent call last):
  File "<frozen runpy>", line 198, in _run_module_as_main
  File "<frozen runpy>", line 88, in _run_code
  File "C:\Users\Володенька\AppData\Roaming\Python\Python312\Scripts\alembic.exe\__main__.py", line 7, in <module>
  File "C:\Users\Володенька\AppData\Roaming\Python\Python312\site-packages\alembic\config.py", line 641, in main
    CommandLine(prog=prog).main(argv=argv)
  File "C:\Users\Володенька\AppData\Roaming\Python\Python312\site-packages\alembic\config.py", line 631, in main
    self.run_cmd(cfg, options)
  File "C:\Users\Володенька\AppData\Roaming\Python\Python312\site-packages\alembic\config.py", line 608, in run_cmd
    fn(
  File "C:\Users\Володенька\AppData\Roaming\Python\Python312\site-packages\alembic\command.py", line 403, in upgrade
    script.run_env()
  File "C:\Users\Володенька\AppData\Roaming\Python\Python312\site-packages\alembic\script\base.py", line 583, in run_env
    util.load_python_file(self.dir, "env.py")
  File "C:\Users\Володенька\AppData\Roaming\Python\Python312\site-packages\alembic\util\pyfiles.py", line 95, in load_python_file
    module = load_module_py(module_id, path)
             ^^^^^^^^^^^^^^^^^^^^^^^^^^^^^^^
  File "C:\Users\Володенька\AppData\Roaming\Python\Python312\site-packages\alembic\util\pyfiles.py", line 113, in load_module_py
    spec.loader.exec_module(module)  # type: ignore
    ^^^^^^^^^^^^^^^^^^^^^^^^^^^^^^^
  File "<frozen importlib._bootstrap_external>", line 995, in exec_module
  File "<frozen importlib._bootstrap>", line 488, in _call_with_frames_removed
  File "C:\Dev\CRM_2.0\backend\crm\migrations\env.py", line 59, in <module>
    run_migrations_online()
  File "C:\Dev\CRM_2.0\backend\crm\migrations\env.py", line 43, in run_migrations_online
    asyncio.run(do_run_migrations())
  File "C:\Program Files\Python312\Lib\asyncio\runners.py", line 194, in run
    return runner.run(main)
           ^^^^^^^^^^^^^^^^
  File "C:\Program Files\Python312\Lib\asyncio\runners.py", line 118, in run
    return self._loop.run_until_complete(task)
           ^^^^^^^^^^^^^^^^^^^^^^^^^^^^^^^^^^^
  File "C:\Program Files\Python312\Lib\asyncio\base_events.py", line 685, in run_until_complete
    return future.result()
           ^^^^^^^^^^^^^^^
  File "C:\Dev\CRM_2.0\backend\crm\migrations\env.py", line 39, in do_run_migrations
    async with connectable.connect() as connection:
  File "C:\Users\Володенька\AppData\Roaming\Python\Python312\site-packages\sqlalchemy\ext\asyncio\base.py", line 121, in __aenter__
    return await self.start(is_ctxmanager=True)
           ^^^^^^^^^^^^^^^^^^^^^^^^^^^^^^^^^^^^
  File "C:\Users\Володенька\AppData\Roaming\Python\Python312\site-packages\sqlalchemy\ext\asyncio\engine.py", line 273, in start
    await greenlet_spawn(self.sync_engine.connect)
  File "C:\Users\Володенька\AppData\Roaming\Python\Python312\site-packages\sqlalchemy\util\_concurrency_py3k.py", line 201, in greenlet_spawn
    result = context.throw(*sys.exc_info())
             ^^^^^^^^^^^^^^^^^^^^^^^^^^^^^^
  File "C:\Users\Володенька\AppData\Roaming\Python\Python312\site-packages\sqlalchemy\engine\base.py", line 3280, in connect
    return self._connection_cls(self)
           ^^^^^^^^^^^^^^^^^^^^^^^^^^
  File "C:\Users\Володенька\AppData\Roaming\Python\Python312\site-packages\sqlalchemy\engine\base.py", line 146, in __init__
    self._dbapi_connection = engine.raw_connection()
                             ^^^^^^^^^^^^^^^^^^^^^^^
  File "C:\Users\Володенька\AppData\Roaming\Python\Python312\site-packages\sqlalchemy\engine\base.py", line 3304, in raw_connection
    return self.pool.connect()
           ^^^^^^^^^^^^^^^^^^^
  File "C:\Users\Володенька\AppData\Roaming\Python\Python312\site-packages\sqlalchemy\pool\base.py", line 449, in connect
    return _ConnectionFairy._checkout(self)
           ^^^^^^^^^^^^^^^^^^^^^^^^^^^^^^^^
  File "C:\Users\Володенька\AppData\Roaming\Python\Python312\site-packages\sqlalchemy\pool\base.py", line 1263, in _checkout
    fairy = _ConnectionRecord.checkout(pool)
            ^^^^^^^^^^^^^^^^^^^^^^^^^^^^^^^^
  File "C:\Users\Володенька\AppData\Roaming\Python\Python312\site-packages\sqlalchemy\pool\base.py", line 712, in checkout
    rec = pool._do_get()
          ^^^^^^^^^^^^^^
  File "C:\Users\Володенька\AppData\Roaming\Python\Python312\site-packages\sqlalchemy\pool\impl.py", line 308, in _do_get
    return self._create_connection()
           ^^^^^^^^^^^^^^^^^^^^^^^^^
  File "C:\Users\Володенька\AppData\Roaming\Python\Python312\site-packages\sqlalchemy\pool\base.py", line 390, in _create_connection
    return _ConnectionRecord(self)
           ^^^^^^^^^^^^^^^^^^^^^^^
  File "C:\Users\Володенька\AppData\Roaming\Python\Python312\site-packages\sqlalchemy\pool\base.py", line 674, in __init__
    self.__connect()
  File "C:\Users\Володенька\AppData\Roaming\Python\Python312\site-packages\sqlalchemy\pool\base.py", line 900, in __connect
    with util.safe_reraise():
  File "C:\Users\Володенька\AppData\Roaming\Python\Python312\site-packages\sqlalchemy\util\langhelpers.py", line 146, in __exit__
    raise exc_value.with_traceback(exc_tb)
  File "C:\Users\Володенька\AppData\Roaming\Python\Python312\site-packages\sqlalchemy\pool\base.py", line 896, in __connect
    self.dbapi_connection = connection = pool._invoke_creator(self)
                                         ^^^^^^^^^^^^^^^^^^^^^^^^^^
  File "C:\Users\Володенька\AppData\Roaming\Python\Python312\site-packages\sqlalchemy\engine\create.py", line 643, in connect
    return dialect.connect(*cargs, **cparams)
           ^^^^^^^^^^^^^^^^^^^^^^^^^^^^^^^^^^
  File "C:\Users\Володенька\AppData\Roaming\Python\Python312\site-packages\sqlalchemy\engine\default.py", line 617, in connect
    return self.loaded_dbapi.connect(*cargs, **cparams)
           ^^^^^^^^^^^^^^^^^^^^^^^^^^^^^^^^^^^^^^^^^^^^
  File "C:\Users\Володенька\AppData\Roaming\Python\Python312\site-packages\sqlalchemy\dialects\postgresql\asyncpg.py", line 937, in connect
    await_only(creator_fn(*arg, **kw)),
    ^^^^^^^^^^^^^^^^^^^^^^^^^^^^^^^^^^
  File "C:\Users\Володенька\AppData\Roaming\Python\Python312\site-packages\sqlalchemy\util\_concurrency_py3k.py", line 131, in await_only
    return current.driver.switch(awaitable)  # type: ignore[no-any-return]
           ^^^^^^^^^^^^^^^^^^^^^^^^^^^^^^^^
  File "C:\Users\Володенька\AppData\Roaming\Python\Python312\site-packages\sqlalchemy\util\_concurrency_py3k.py", line 196, in greenlet_spawn
    value = await result
            ^^^^^^^^^^^^
  File "C:\Users\Володенька\AppData\Roaming\Python\Python312\site-packages\asyncpg\connection.py", line 2329, in connect
    return await connect_utils._connect(
           ^^^^^^^^^^^^^^^^^^^^^^^^^^^^^
  File "C:\Users\Володенька\AppData\Roaming\Python\Python312\site-packages\asyncpg\connect_utils.py", line 1017, in _connect
    raise last_error or exceptions.TargetServerAttributeNotMatched(
  File "C:\Users\Володенька\AppData\Roaming\Python\Python312\site-packages\asyncpg\connect_utils.py", line 991, in _connect
    conn = await _connect_addr(
           ^^^^^^^^^^^^^^^^^^^^
  File "C:\Users\Володенька\AppData\Roaming\Python\Python312\site-packages\asyncpg\connect_utils.py", line 828, in _connect_addr
    return await __connect_addr(params, True, *args)
           ^^^^^^^^^^^^^^^^^^^^^^^^^^^^^^^^^^^^^^^^^
  File "C:\Users\Володенька\AppData\Roaming\Python\Python312\site-packages\asyncpg\connect_utils.py", line 873, in __connect_addr
    tr, pr = await connector
             ^^^^^^^^^^^^^^^
  File "C:\Users\Володенька\AppData\Roaming\Python\Python312\site-packages\asyncpg\connect_utils.py", line 752, in _create_ssl_connection
    do_ssl_upgrade = await pr.on_data
                     ^^^^^^^^^^^^^^^^
  File "C:\Program Files\Python312\Lib\asyncio\proactor_events.py", line 286, in _loop_reading
    length = fut.result()
             ^^^^^^^^^^^^
  File "C:\Program Files\Python312\Lib\asyncio\windows_events.py", line 798, in _poll
    value = callback(transferred, key, ov)
            ^^^^^^^^^^^^^^^^^^^^^^^^^^^^^^
  File "C:\Program Files\Python312\Lib\asyncio\windows_events.py", line 465, in finish_socket_func
    raise ConnectionResetError(*exc.args)
ConnectionResetError: [WinError 64] Указанное сетевое имя более недоступно
